Workbook

Sheet Dashboard
A1: Personal Ride-Data Analysis Dashboard
A2: Uber ride history — Sep 2024 to Aug 2025 (Bangalore)
A4: Total Trips Requested | C4: Completed Trips | E4: Cancellation Rate | G4: Total Spend (INR)
A5: =COUNTA('Trip Data'!A2:A49) -> 47 | C5: =COUNTIF('Trip Data'!F2:F49,"Completed") -> 27 | E5: =COUNTIF('Trip Data'!F2:F49,"Rider Canceled")/COUNTA('Trip Data'!F2:F49) -> 0.36170213 | G5: =SUM('Trip Data'!J2:J49) -> 1536.9
A8: Avg Fare per Trip (INR) | C8: Avg Wait — Completed (min) | E8: Avg Wait — Canceled (min) | G8: Home→Office Share
A9: =AVERAGEIF('Trip Data'!F2:F49,"Completed",'Trip Data'!J2:J49) -> 56.922222 | C9: =AVERAGEIFS('Trip Data'!M2:M49,'Trip Data'!F2:F49,"Completed") -> 5.0703704 | E9: =AVERAGEIFS('Trip Data'!M2:M49,'Trip Data'!F2:F49,"Rider Canceled") -> 10.8 | G9: =COUNTIFS('Trip Data'!F2:F49,"Completed",'Trip Data'!N2:N49,"Home Area",'Trip Data'!O2:O49,"Office")/COUNTIF('Trip Data'!F2:F49,"Completed") -> 0.55555556
A12: Chart Data (feeds charts below — do not delete)
A13: Hour | B13: Completed Trips
A14: 6 | B14: =COUNTIFS('Trip Data'!F2:F49,"Completed",'Trip Data'!C2:C49,6) -> 0
A15: 7 | B15: =COUNTIFS('Trip Data'!F2:F49,"Completed",'Trip Data'!C2:C49,7) -> 0
A16: 8 | B16: =COUNTIFS('Trip Data'!F2:F49,"Completed",'Trip Data'!C2:C49,8) -> 0
A17: 9 | B17: =COUNTIFS('Trip Data'!F2:F49,"Completed",'Trip Data'!C2:C49,9) -> 9
A18: 10 | B18: =COUNTIFS('Trip Data'!F2:F49,"Completed",'Trip Data'!C2:C49,10) -> 0
A19: 11 | B19: =COUNTIFS('Trip Data'!F2:F49,"Completed",'Trip Data'!C2:C49,11) -> 0
A20: 12 | B20: =COUNTIFS('Trip Data'!F2:F49,"Completed",'Trip Data'!C2:C49,12) -> 1
A21: 13 | B21: =COUNTIFS('Trip Data'!F2:F49,"Completed",'Trip Data'!C2:C49,13) -> 6
A22: 14 | B22: =COUNTIFS('Trip Data'!F2:F49,"Completed",'Trip Data'!C2:C49,14) -> 0
A23: 15 | B23: =COUNTIFS('Trip Data'!F2:F49,"Completed",'Trip Data'!C2:C49,15) -> 1
A24: 16 | B24: =COUNTIFS('Trip Data'!F2:F49,"Completed",'Trip Data'!C2:C49,16) -> 0
A25: 17 | B25: =COUNTIFS('Trip Data'!F2:F49,"Completed",'Trip Data'!C2:C49,17) -> 1
A26: 18 | B26: =COUNTIFS('Trip Data'!F2:F49,"Completed",'Trip Data'!C2:C49,18) -> 0
A27: 19 | B27: =COUNTIFS('Trip Data'!F2:F49,"Completed",'Trip Data'!C2:C49,19) -> 0
A28: 20 | B28: =COUNTIFS('Trip Data'!F2:F49,"Completed",'Trip Data'!C2:C49,20) -> 1
A29: 21 | B29: =COUNTIFS('Trip Data'!F2:F49,"Completed",'Trip Data'!C2:C49,21) -> 4
A30: 22 | B30: =COUNTIFS('Trip Data'!F2:F49,"Completed",'Trip Data'!C2:C49,22) -> 1
A31: 23 | B31: =COUNTIFS('Trip Data'!F2:F49,"Completed",'Trip Data'!C2:C49,23) -> 1
A33: Month | B33: Trips | C33: Spend (INR)
A34: 2024-09 | B34: =COUNTIFS('Trip Data'!F2:F49,"Completed",'Trip Data'!E2:E49,"2024-09") -> 1 | C34: =SUMIFS('Trip Data'!J2:J49,'Trip Data'!F2:F49,"Completed",'Trip Data'!E2:E49,"2024-09") -> 43
A35: 2024-10 | B35: =COUNTIFS('Trip Data'!F2:F49,"Completed",'Trip Data'!E2:E49,"2024-10") -> 2 | C35: =SUMIFS('Trip Data'!J2:J49,'Trip Data'!F2:F49,"Completed",'Trip Data'!E2:E49,"2024-10") -> 139
A36: 2024-11 | B36: =COUNTIFS('Trip Data'!F2:F49,"Completed",'Trip Data'!E2:E49,"2024-11") -> 1 | C36: =SUMIFS('Trip Data'!J2:J49,'Trip Data'!F2:F49,"Completed",'Trip Data'!E2:E49,"2024-11") -> 94
A37: 2024-12 | B37: =COUNTIFS('Trip Data'!F2:F49,"Completed",'Trip Data'!E2:E49,"2024-12") -> 1 | C37: =SUMIFS('Trip Data'!J2:J49,'Trip Data'!F2:F49,"Completed",'Trip Data'!E2:E49,"2024-12") -> 45
A38: 2025-01 | B38: =COUNTIFS('Trip Data'!F2:F49,"Completed",'Trip Data'!E2:E49,"2025-01") -> 3 | C38: =SUMIFS('Trip Data'!J2:J49,'Trip Data'!F2:F49,"Completed",'Trip Data'!E2:E49,"2025-01") -> 119
A39: 2025-02 | B39: =COUNTIFS('Trip Data'!F2:F49,"Completed",'Trip Data'!E2:E49,"2025-02") -> 9 | C39: =SUMIFS('Trip Data'!J2:J49,'Trip Data'!F2:F49,"Completed",'Trip Data'!E2:E49,"2025-02") -> 344.9
A40: 2025-03 | B40: =COUNTIFS('Trip Data'!F2:F49,"Completed",'Trip Data'!E2:E49,"2025-03") -> 0 | C40: =SUMIFS('Trip Data'!J2:J49,'Trip Data'!F2:F49,"Completed",'Trip Data'!E2:E49,"2025-03") -> 0
A41: 2025-04 | B41: =COUNTIFS('Trip Data'!F2:F49,"Completed",'Trip Data'!E2:E49,"2025-04") -> 3 | C41: =SUMIFS('Trip Data'!J2:J49,'Trip Data'!F2:F49,"Completed",'Trip Data'!E2:E49,"2025-04") -> 128.89
A42: 2025-05 | B42: =COUNTIFS('Trip Data'!F2:F49,"Completed",'Trip Data'!E2:E49,"2025-05") -> 2 | C42: =SUMIFS('Trip Data'!J2:J49,'Trip Data'!F2:F49,"Completed",'Trip Data'!E2:E49,"2025-05") -> 80.16
A43: 2025-06 | B43: =COUNTIFS('Trip Data'!F2:F49,"Completed",'Trip Data'!E2:E49,"2025-06") -> 4 | C43: =SUMIFS('Trip Data'!J2:J49,'Trip Data'!F2:F49,"Completed",'Trip Data'!E2:E49,"2025-06") -> 173.02
A44: 2025-08 | B44: =COUNTIFS('Trip Data'!F2:F49,"Completed",'Trip Data'!E2:E49,"2025-08") -> 1 | C44: =SUMIFS('Trip Data'!J2:J49,'Trip Data'!F2:F49,"Completed",'Trip Data'!E2:E49,"2025-08") -> 369.93
A46: Vehicle Type | B46: Requests
A47: AUTO Agram | B47: =COUNTIF('Trip Data'!G2:G49,"AUTO Agram") -> 13
...

Sheet Trip Data
A1: Date | B1: Time | C1: Hour | D1: Day of Week | E1: Month | F1: Status | G1: Vehicle Type | H1: Distance (mi) | I1: Duration (min) | J1: Fare (INR) | K1: Surge Multiplier | L1: Is Surged | M1: ETA (min) | N1: Pickup Area | O1: Dropoff Area | P1: Fare per Mile (INR)
A2: 2024-09-26 | B2: 09:49 | C2: 9 | D2: Thursday | E2: 2024-09 | F2: Rider Canceled | G2: AUTO Agram | J2: 0 | L2: =FALSE() -> FALSE | O2: Office | P2: =IFERROR(J2/H2,"")
A3: 2024-09-26 | B3: 09:55 | C3: 9 | D3: Thursday | E3: 2024-09 | F3: Rider Canceled | G3: AUTO Agram | J3: 0 | L3: =FALSE() -> FALSE | O3: Office | P3: =IFERROR(J3/H3,"")
A4: 2024-09-27 | B4: 13:52 | C4: 13 | D4: Friday | E4: 2024-09 | F4: Completed | G4: Moto_short | H4: 1.667597 | I4: 9.8 | J4: 43 | K4: 1 | L4: =FALSE() -> FALSE | M4: 6.1 | N4: Home Area | O4: Office | P4: =IFERROR(J4/H4,"") -> 25.785606
A5: 2024-09-30 | B5: 09:56 | C5: 9 | D5: Monday | E5: 2024-09 | F5: Rider Canceled | G5: AUTO Agram | J5: 0 | L5: =FALSE() -> FALSE | M5: 12 | O5: Office | P5: =IFERROR(J5/H5,"")
A6: 2024-10-08 | B6: 09:34 | C6: 9 | D6: Tuesday | E6: 2024-10 | F6: Completed | G6: AUTO Agram | H6: 2.424186 | I6: 13.8 | J6: 96 | K6: 1 | L6: =FALSE() -> FALSE | M6: 6.4 | N6: Home Area | O6: Other | P6: =IFERROR(J6/H6,"") -> 39.600922
A7: 2024-10-09 | B7: 09:54 | C7: 9 | D7: Wednesday | E7: 2024-10 | F7: Completed | G7: Moto_short | H7: 1.65987 | I7: 7.8 | J7: 43 | K7: 1 | L7: =FALSE() -> FALSE | M7: 6.2 | N7: Home Area | O7: Office | P7: =IFERROR(J7/H7,"") -> 25.905643
A8: 2024-11-02 | B8: 21:54 | C8: 21 | D8: Saturday | E8: 2024-11 | F8: Rider Canceled | G8: Moto Saver | J8: 0 | L8: =FALSE() -> FALSE | M8: 8.2 | O8: Other | P8: =IFERROR(J8/H8,"")
A9: 2024-11-12 | B9: 09:45 | C9: 9 | D9: Tuesday | E9: 2024-11 | F9: Rider Canceled | G9: AUTO Agram | J9: 0 | L9: =FALSE() -> FALSE | M9: 6.9 | O9: Office | P9: =IFERROR(J9/H9,"")
A10: 2024-11-19 | B10: 09:08 | C10: 9 | D10: Tuesday | E10: 2024-11 | F10: Completed | G10: AUTO Agram | H10: 1.666445 | I10: 12.1 | J10: 94 | K10: 1 | L10: =FALSE() -> FALSE | M10: 7.4 | N10: Home Area | O10: Office | P10: =IFERROR(J10/H10,"") -> 56.407502
A11: 2024-12-02 | B11: 13:27 | C11: 13 | D11: Monday | E11: 2024-12 | F11: Completed | G11: Moto_short | H11: 1.65694 | I11: 8.6 | J11: 45 | K11: 1 | L11: =FALSE() -> FALSE | M11: 6.2 | N11: Home Area | O11: Office | P11: =IFERROR(J11/H11,"") -> 27.158497
A12: 2025-01-02 | B12: 08:24 | C12: 8 | D12: Thursday | E12: 2025-01 | F12: Rider Canceled | G12: AUTO Agram | J12: 0 | L12: =FALSE() -> FALSE | O12: Home Area | P12: =IFERROR(J12/H12,"")
A13: 2025-01-06 | B13: 09:57 | C13: 9 | D13: Monday | E13: 2025-01 | F13: Completed | G13: Moto_short | H13: 1.009057 | I13: 7.5 | J13: 47 | K13: 1.1 | L13: =TRUE() -> TRUE | M13: 5.5 | N13: Home Area | O13: Office | P13: =IFERROR(J13/H13,"") -> 46.578142
A14: 2025-01-16 | B14: 13:31 | C14: 13 | D14: Thursday | E14: 2025-01 | F14: Rider Canceled | G14: Moto Saver | J14: 0 | L14: =FALSE() -> FALSE | M14: 7.2 | O14: Office | P14: =IFERROR(J14/H14,"")
A15: 2025-01-22 | B15: 13:10 | C15: 13 | D15: Wednesday | E15: 2025-01 | F15: Completed | G15: Moto Saver | H15: 1.661348 | I15: 9.7 | J15: 33 | K15: 1 | L15: =FALSE() -> FALSE | M15: 2.5 | N15: Home Area | O15: Office | P15: =IFERROR(J15/H15,"") -> 19.863388
A16: 2025-01-27 | B16: 09:55 | C16: 9 | D16: Monday | E16: 2025-01 | F16: Completed | G16: Moto Saver | H16: 1.588882 | I16: 8.5 | J16: 39 | K16: 1.2 | L16: =TRUE() -> TRUE | M16: 7.4 | N16: Home Area | O16: Office | P16: =IFERROR(J16/H16,"") -> 24.545561
A17: 2025-02-05 | B17: 09:55 | C17: 9 | D17: Wednesday | E17: 2025-02 | F17: Rider Canceled | G17: Moto Saver | J17: 0 | L17: =TRUE() -> TRUE | O17: Office | P17: =IFERROR(J17/H17,"")
A18: 2025-02-05 | B18: 10:06 | C18: 10 | D18: Wednesday | E18: 2025-02 | F18: Rider Canceled | G18: Moto Saver | J18: 0 | L18: =TRUE() -> TRUE | M18: 20.1 | O18: Office | P18: =IFERROR(J18/H18,"")
A19: 2025-02-06 | B19: 09:52 | C19: 9 | D19: Thursday | E19: 2025-02 | F19: Completed | G19: Moto Saver | H19: 1.59564 | I19: 9.2 | J19: 36 | K19: 1.1 | L19: =TRUE() -> TRUE | M19: 5.9 | N19: Home Area | O19: Office | P19: =IFERROR(J19/H19,"") -> 22.56148
A20: 2025-02-07 | B20: 13:58 | C20: 13 | D20: Friday | E20: 2025-02 | F20: Completed | G20: Moto Saver | H20: 1.588099 | I20: 7.3 | J20: 33 | K20: 1 | L20: =FALSE() -> FALSE | M20: 5 | N20: Home Area | O20: Office | P20: =IFERROR(J20/H20,"") -> 20.779561
A21: 2025-02-10 | B21: 09:47 | C21: 9 | D21: Monday | E21: 2025-02 | F21: Completed | G21: Moto Saver | H21: 1.603458 | I21: 14.5 | J21: 38 | K21: 1.1 | L21: =TRUE() -> TRUE | M21: 6.5 | N21: Home Area | O21: Office | P21: =IFERROR(J21/H21,"") -> 23.698781
A22: 2025-02-11 | B22: 12:23 | C22: 12 | D22: Tuesday | E22: 2025-02 | F22: Completed | G22: Moto Saver | H22: 1.661259 | I22: 7.3 | J22: 33 | K22: 1 | L22: =FALSE() -> FALSE | M22: 3.2 | N22: Home Area | O22: Office | P22: =IFERROR(J22/H22,"") -> 19.864452
A23: 2025-02-12 | B23: 09:27 | C23: 9 | D23: Wednesday | E23: 2025-02 | F23: Completed | G23: Moto Saver | H23: 1.588327 | I23: 10.6 | J23: 40 | K23: 1.2 | L23: =TRUE() -> TRUE | M23: 1.5 | N23: Home Area | O23: Office | P23: =IFERROR(J23/H23,"") -> 25.183731
A24: 2025-02-17 | B24: 09:32 | C24: 9 | D24: Monday | E24: 2025-02 | F24: Completed | G24: Moto Saver | H24: 1.604659 | I24: 10.4 | J24: 44.74 | K24: 1.4 | L24: =TRUE() -> TRUE | M24: 7.9 | N24: Home Area | O24: Office | P24: =IFERROR(J24/H24,"") -> 27.881313
A25: 2025-02-19 | B25: 13:09 | C25: 13 | D25: Wednesday | E25: 2025-02 | F25: Completed | G25: Moto Saver | H25: 1.599026 | I25: 8.6 | J25: 32.81 | K25: 1 | L25: =FALSE() -> FALSE | M25: 5.1 | N25: Home Area | O25: Office | P25: =IFERROR(J25/H25,"") -> 20.518741
A26: 2025-02-21 | B26: 13:20 | C26: 13 | D26: Friday | E26: 2025-02 | F26: Completed | G26: Moto Saver | H26: 1.588289 | I26: 8 | J26: 35.88 | K26: 1.1 | L26: =TRUE() -> TRUE | M26: 8 | N26: Home Area | O26: Office | P26: =IFERROR(J26/H26,"") -> 22.590347
A27: 2025-02-22 | B27: 04:06 | C27: 4 | D27: Saturday | E27: 2025-02 | F27: Completed | G27: Moto Saver | H27: 2.74315 | I27: 8.1 | J27: 51.47 | K27: 1 | L27: =FALSE() -> FALSE | M27: 3.6 | N27: Home Area | O27: Other | P27: =IFERROR(J27/H27,"") -> 18.763101
A28: 2025-03-01 | B28: 10:51 | C28: 10 | D28: Saturday | E28: 2025-03 | F28: Rider Canceled | G28: AUTO Agram | J28: 0 | L28: =FALSE() -> FALSE | M28: 5.8 | O28: Other | P28: =IFERROR(J28/H28,"")
A29: 2025-03-01 | B29: 13:41 | C29: 13 | D29: Saturday | E29: 2025-03 | F29: Rider Canceled | G29: AUTO Agram | J29: 0 | L29: =FALSE() -> FALSE | O29: Home Area | P29: =IFERROR(J29/H29,"")
A30: 2025-03-03 | B30: 09:01 | C30: 9 | D30: Monday | E30: 2025-03 | F30: Unfulfilled | G30: AUTO Agram | H30: 0 | I30: 0 | J30: 0 | K30: 0 | L30: =FALSE() -> FALSE | O30: Other | P30: =IFERROR(J30/H30,"")
A31: 2025-03-03 | B31: 09:43 | C31: 9 | D31: Monday | E31: 2025-03 | F31: Unfulfilled | G31: AUTO Agram | H31: 0 | I31: 0 | J31: 0 | K31: 0 | L31: =FALSE() -> FALSE | O31: Other | P31: =IFERROR(J31/H31,"")
A32: 2025-03-03 | B32: 09:52 | C32: 9 | D32: Monday | E32: 2025-03 | F32: Driver Canceled | G32: AUTO Agram | J32: 0 | L32: =FALSE() -> FALSE | M32: 7.3 | O32: Other | P32: =IFERROR(J32/H32,"")
A33: 2025-04-26 | B33: 22:22 | C33: 22 | D33: Saturday | E33: 2025-04 | F33: Completed | G33: Moto Saver | H33: 1.27333 | I33: 5.3 | J33: 43.21 | K33: 1 | L33: =FALSE() -> FALSE | M33: 2.5 | N33: Vydehi/Vijayanagar | O33: Home Area | P33: =IFERROR(J33/H33,"") -> 33.934644
A34: 2025-04-26 | B34: 23:18 | C34: 23 | D34: Saturday | E34: 2025-04 | F34: Completed | G34: Moto Saver | H34: 1.080879 | I34: 4.4 | J34: 43.98 | K34: 1.1 | L34: =TRUE() -> TRUE | M34: 5.4 | N34: Other | O34: Vydehi/Vijayanagar | P34: =IFERROR(J34/H34,"") -> 40.689106
A35: 2025-04-27 | B35: 20:04 | C35: 20 | D35: Sunday | E35: 2025-04 | F35: Completed | G35: Moto Saver | H35: 1.938847 | I35: 7.7 | J35: 41.7 | K35: 1 | L35: =FALSE() -> FALSE | M35: 7.3 | N35: Home Area | O35: Vydehi/Vijayanagar | P35: =IFERROR(J35/H35,"") -> 21.507628
A36: 2025-05-04 | B36: 21:19 | C36: 21 | D36: Sunday | E36: 2025-05 | F36: Completed | G36: Moto Saver | H36: 1.639482 | I36: 6.8 | J36: 37.26 | K36: 1.1 | L36: =TRUE() -> TRUE | M36: 2.4 | N36: Vydehi/Vijayanagar | O36: Home Area | P36: =IFERROR(J36/H36,"") -> 22.726691
A37: 2025-05-04 | B37: 15:14 | C37: 15 | D37: Sunday | E37: 2025-05 | F37: Rider Canceled | G37: Moto Saver | J37: 0 | L37: =TRUE() -> TRUE | N37: Vydehi/Vijayanagar | O37: Home Area | P37: =IFERROR(J37/H37,"")
A38: 2025-05-05 | B38: 00:34 | C38: 0 | D38: Monday | E38: 2025-05 | F38: Rider Canceled | G38: Moto Saver | J38: 0 | L38: =FALSE() -> FALSE | M38: 5.2 | N38: Home Area | O38: Vydehi/Vijayanagar | P38: =IFERROR(J38/H38,"")
A39: 2025-05-05 | B39: 00:41 | C39: 0 | D39: Monday | E39: 2025-05 | F39: Completed | G39: Moto Saver | H39: 1.684274 | I39: 6.5 | J39: 42.9 | K39: 1 | L39: =FALSE() -> FALSE | M39: 5.9 | N39: Home Area | O39: Vydehi/Vijayanagar | P39: =IFERROR(J39/H39,"") -> 25.470915
A40: 2025-05-24 | B40: 23:59 | C40: 23 | D40: Saturday | E40: 2025-05 | F40: Rider Canceled | G40: Moto Saver | J40: 0 | L40: =TRUE() -> TRUE | M40: 11 | N40: Vydehi/Vijayanagar | O40: Home Area | P40: =IFERROR(J40/H40,"")
...

Sheet Insights
A1: Key Insights
B3: • Commute-dominated usage: 19 of 27 completed trips (70%) started from the same residential area, and 15 of 27 (56%) ended at the same office building — this is primarily a home-to-office commute tool, not general-purpose travel.
B5: • High cancellation rate driven by wait time: 36% of all 47 requested trips were canceled by the rider. Canceled trips had an average estimated wait of ~10.8 minutes, versus ~5.1 minutes for trips that were completed — wait time appears to be the dominant driver of cancellations.
B7: • Peak usage at commute hours: rides cluster heavily around 9 AM and 1 PM, consistent with a morning office commute and a midday (lunch or return) trip.
B9: • Cost-conscious vehicle choice: 70% of all requests were for 2-wheeler options (Moto Saver / Moto Short) rather than car options — the cheaper mode is strongly preferred for these short commute-distance trips.
B11: • Surge pricing effect is real but modest: on a fare-per-mile basis, surge-tagged trips cost about 8% more per mile than non-surge trips (₹30.6/mi vs ₹28.3/mi) once trip mix is controlled for.
B13: • Total spend: ₹1,536.90 across 27 completed trips (Sep 2024 – Aug 2025), averaging ₹56.92/trip — or ₹44.88/trip excluding one 21-mile outlier ride, which is more representative of the typical commute cost.
B15: • Driver ratings given: averaged 4.69/5 across 26 rated trips, with only 2 one-star ratings — indicating generally positive driver experiences on this route.
